<?xml version="1.0" ?>
<mujoco model="harpy_sophisticated_complete">
  <compiler angle="degree" coordinate="local" inertiafromgeom="true"/>
  <default>
    <joint armature="0.01" damping="0.1" limited="true"/>
    <geom conaffinity="0" condim="3" density="5.0" friction="1 0.5 0.001" rgba="0.3 0.3 0.3 1"/>
    <motor ctrllimited="true" ctrlrange="-1 1"/>
    <default class='collision'>
      <!-- User parameter for geoms is used to identify collision types -->
      <geom material='collision' contype='1' user='2'/>
    </default>
    <default class='collision_left'>
      <geom contype='2' conaffinity='4'/>
    </default>
    <default class='collision_right'>
      <geom contype='4' conaffinity='2'/>
    </default>
    <default class='obstacle'>
      <geom material='obstacle' condim='3' contype='8' conaffinity='15' user='1'/>
    </default>
  </default>
  
  <option gravity="0 0 -9.81" integrator="RK4" timestep="0.0005" tolerance="1e-8" solver="Newton" iterations="100" jacobian="dense"/>
  
  <visual>
    <global offwidth="1200" offheight="800"/>
    <quality shadowsize='4096'/>
    <map znear='0.05'/>
  </visual>
  
  <asset>
    <texture type='skybox' builtin='gradient' width='128' height='128' rgb1='0.4 0.6 0.8' rgb2='0 0 0'/>
    <texture name="plane" type="2d" builtin="checker" rgb1="0.2 0.2 0.2" rgb2="0.3 0.3 0.3" width="512" height="512"/>
    <!-- <material name="grid" texture="grid" texrepeat="8 8" reflectance="0.2"/> -->
    <material name="plane" texture="plane" texrepeat="8 8" reflectance="0.2" texuniform="true"/>
    <material name='collision' rgba='0.1 0.5 0.9 0'/>
    <material name='obstacle'  rgba='0.2 0.6 0.2 1'/>
    <hfield name="hill" nrow='512' ncol='512' size="60 60 2 1"/>
  </asset>
  
  <worldbody>
    <light cutoff="100" diffuse="1 1 1" dir="0 0 -1" directional="true" exponent="1" pos="0 0 4" specular="0.1 0.1 0.1"/>
    <!-- <geom name="floor" pos="0 0 -0.01" size="0 0 1" type="plane" material="plane"/> -->
    <geom name="floor" pos="0 0 -0.1" size="10 10 0.05" type="box" material="plane" condim="3" conaffinity="15" friction="1.0 0.5 0.001"/>
    <!-- <geom name='floor' pos='0.0 0 -0.01' type='hfield' hfield='hill' material='plane' condim='3' conaffinity='15' priority="1"/> -->
    <!-- <light mode='trackcom' pos='0 0 5' dir='0 0 -1'/>
    <light directional='true' pos='0 0 3' dir='0 0 -1' diffuse='0.2 0.2 0.2' specular='0 0 0'/> -->

    <!-- Main robot body - Compact Rectangular Torso (True Harpy Design) -->
    <body name="harpy-torso" pos="0 0 1.2">
      <!-- Main torso body (compact rectangular/block structure) -->
      <inertial pos='0 0 0' mass='8.0' diaginertia='0.1 0.1 0.1'/>
      <joint type='slide' axis='1 0 0' limited='false'/>
      <joint type='slide' axis='0 1 0' limited='false'/>
      <joint type='slide' axis='0 0 1' limited='false' ref='1.2'/>
      <joint type='ball' limited='false'/>
      
      <!-- Main torso - compact rectangular/block structure -->
      <geom type='box' size='0.18 0.12 0.15' pos='0 0 0' rgba='0.3 0.3 0.3 1'/>
      
      <!-- FRONT SIDE INDICATORS -->
      <!-- Front LED strip (bright blue) -->
      <geom type='box' size='0.12 0.01 0.02' pos='0.09 0 0.05' rgba='0.0 0.8 1.0 1'/>
      <!-- Front camera/sensor housing -->
      <geom type='cylinder' size='0.03 0.02' pos='0.09 0 0' rgba='0.1 0.1 0.1 1'/>
      <!-- Front directional arrow -->
      <geom type='box' size='0.04 0.01 0.01' pos='0.08 0.03 0.02' rgba='1.0 0.3 0.3 1'/>
      <geom type='box' size='0.02 0.02 0.01' pos='0.07 0.025 0.02' rgba='1.0 0.3 0.3 1'/>
      
      <!-- Control system mounting points (visible details) -->
      <geom type='box' size='0.15 0.08 0.02' pos='0 0 0.06' rgba='0.1 0.4 0.1 0.8'/>
      <geom type='box' size='0.12 0.06 0.02' pos='0 0 -0.05' rgba='0.2 0.2 0.4 0.8'/>
      
      <geom type='sphere' size='0.15' pos='0.02 0 0.02' class='collision'/>
      <!-- IMU sensor site -->
      <site name='imu' size='0.01' pos='0 0 0'/>
      
      <!-- === THRUSTER MOUNTING SYSTEM (Extension bars from center) === -->
      
      <!-- LEFT EXTENSION BAR - connecting cylinder to left side face of torso -->
      <body name="left_extension_bar" pos="-0.15 0.12 0.0" xyaxes="1 0 0 0 0 1">
          <inertial pos="0 0 0" mass="0.3" diaginertia="0.001 0.001 0.001"/>
          <geom name="left_extension_geom" type="cylinder" size="0.04 0.18" pos="0.15 0 0" rgba="0.3 0.3 0.3 1" class='collision'/>
          
          <!-- LEFT THRUSTER PITCH JOINT - shoulder joint at center of far end face -->
          <body name='left-thruster-pitch' pos='0.15 0 -0.18' xyaxes='1 0 0 0 0 1'>
            <inertial pos='0 0 0' mass='0.5' diaginertia='0.001 0.001 0.001'/>
            <joint name='thruster_left_pitch' type='hinge' range='-90 90' axis="0 1 0" damping='1' armature='0.05'/>
            <!-- Shoulder joint geometry -->
            <geom type='sphere' size='0.03' pos='0 0 0' rgba='0.5 0.5 0.5 1'/>

              <!-- Thruster housing -->
              <body name="thruster_left" pos="0 0 -0.08">
                  <inertial pos="0 0 0" mass="0.3" diaginertia="0.0005 0.0005 0.0005"/>
                  
                  <geom name="thruster_left_housing" type="cylinder" 
                        size="0.04 0.08" 
                        pos="0 -0.06 0.12" 
                        rgba="1.0 1.0 1.0 1"
                        class="collision"/>
                  
                  <!-- Thruster force site -->
                  <site name="thruster_left_site" 
                        pos="0 -0.06 0.08" 
                        size="0.01" 
                        type="sphere" 
                        rgba="1 0 0 0.5"/>
              </body>
          </body>
      </body>

      <!-- RIGHT EXTENSION BAR - connecting cylinder to right side face of torso -->
      <body name="right_extension_bar" pos="-0.15 -0.12 0.0" xyaxes="1 0 0 0 0 1">
          <inertial pos="0 0 0" mass="0.3" diaginertia="0.001 0.001 0.001"/>
          <geom name="right_extension_geom" type="cylinder" size="0.04 0.18" pos="0.15 0 0" rgba="0.3 0.3 0.3 1" class='collision'/>
          
          <!-- RIGHT THRUSTER PITCH JOINT - at far end of extension rod (away from torso) -->
          <body name="thruster_right_pitch" pos="0.15 0 0.18" xyaxes="1 0 0 0 0 1">
              <inertial pos="0 0 0" mass="0.5" diaginertia="0.001 0.001 0.001"/>
              <joint name="thruster_right_pitch" type="hinge" range="-90 90" axis="0 1 0" damping="1" armature="0.05"/>
              
              <!-- Shoulder joint geometry -->
              <geom type='sphere' size='0.03' pos='0 0 0' rgba='0.5 0.5 0.5 1'/>
              
              <!-- Thruster housing -->
              <body name="thruster_right" pos="0 0 -0.08">
                  <inertial pos="0 0 0" mass="0.3" diaginertia="0.0005 0.0005 0.0005"/>
                  
                  <geom name="thruster_right_housing" type="cylinder" 
                        size="0.04 0.08" 
                        pos="0 0.06 0.12" 
                        rgba="0.8 0.8 0.8 1"
                        class="collision"/>
                  
                  <!-- Thruster force site -->
                  <site name="thruster_right_site" 
                        pos="0 0.06 0.08" 
                        size="0.01" 
                        type="sphere" 
                        rgba="1 0 0 0.5"/>
              </body>
          </body>
      </body>
      
      <!-- COMPLETE CASSIE LEG STRUCTURE - LEFT LEG -->
      <body name='left-hip-roll' pos='0.021 0.135 -0.2' xyaxes='0 0 -1 0 1 0'>
        <inertial pos='-0.01793 0.0001 -0.04428' mass='1.82' fullinertia='0.003431 0.003793 0.002135 -6.65e-07 -0.00084 3.99e-06'/>
        <joint name='left-hip-roll' type='hinge' range='-15 22.5' damping='1' armature='0.038125'/>
        <!-- Sophisticated hip roll geometry -->
        <geom type='cylinder' size='0.06 0.1' pos='0 0 0' rgba='1.0 0.0 0.0 1'/>
        <!-- Visible gears/internal workings -->
        <geom type='cylinder' size='0.04 0.02' pos='0 0 0.08' rgba='0.1 0.3 0.1 0.8'/>
        <geom type='cylinder' size='0.04 0.02' pos='0 0 -0.08' rgba='0.1 0.3 0.1 0.8'/>
        
        <body name='left-hip-yaw' pos='0 0 -0.07' xyaxes='0 0 1 0 1 0'>
          <inertial pos='0 -1e-05 -0.034277' mass='1.171' fullinertia='0.002443 0.002803 0.000842 -4e-08 2.462e-07 -2.71e-08'/>
          <joint name='left-hip-yaw' type='hinge' range='-22.5 22.5' damping='1' armature='0.038125'/>
          <!-- Sophisticated hip yaw geometry -->
          <geom type='capsule' size='0.05' fromto='-0.025 0 -0.015 0.025 0 -0.015' rgba='1.0 0.0 0.0 1'/>
          
          <body name='left-hip-pitch' pos='0 0 -0.09' xyaxes='0 0 -1 1 0 0'>
            <inertial pos='0.05946 5e-05 -0.03581' mass='5.52' fullinertia='0.010898 0.029714 0.030257 -0.0002669 -5.721e-05 9.17e-06'/>
            <joint name='left-hip-pitch' type='hinge' range='-50 80' damping='1' armature='0.09344'/>
            <!-- Sophisticated hip pitch geometry -->
            <geom type='capsule' size='0.08' fromto='0 0 -0.04 0.12 0 -0.0355' rgba='1.0 0.0 0.0 1' class='collision'/>
            
            <body name='left-achilles-rod' pos='0 0 0.045' xyaxes='0.7922 -0.60599 -0.072096 0.60349 0.79547 -0.054922'>
              <inertial pos='0.24719 0 0' mass='0.1567' fullinertia='3.754e-06 0.004487 0.004488 -3.74e-08 -1.61e-08 0'/>
              <joint name='left-achilles-rod' type='ball' limited='false' damping='0.01'/>
              <!-- Sophisticated achilles rod -->
              <geom type='capsule' size='0.01' fromto='0 0 0 0.24719 0 0' rgba='1.0 0.0 0.0 1'/>
            </body>
            
            <body name='left-knee' pos='0.12 0 0.0045' xyaxes='0.70711 -0.70711 0 0.70711 0.70711 0'>
              <inertial pos='0.023 0.03207 -0.002181' mass='0.7578' fullinertia='0.001376 0.0010335 0.0021637 -0.00039744 -4.085e-05 -5.374e-05'/>
              <joint name='left-knee' type='hinge' ref='-45' range='-164 -37' damping='1' armature='0.09344'/>
              <!-- Sophisticated knee joint -->
              <geom type='sphere' size='0.08' pos='0.023 0.03207 -0.002181' rgba='1.0 0.0 0.0 1'/>
              
              <body name='left-knee-spring' pos='0.06068 0.08241 0'>
                <inertial pos='0.0836 0.0034 0' mass='0.186' fullinertia='5.215e-05 0.00041205 0.0003669 6.87e-06 0 0'/>
                <!-- Sophisticated knee spring -->
                <geom type='capsule' size='0.02' fromto='0 0 0 0.0836 0.0034 0' rgba='1.0 0.0 0.0 1'/>
              </body>
              
              <body name='left-shin' pos='0.06068 0.04741 0'>
                <inertial pos='0.18338 0.001169 0.0002123' mass='0.577' fullinertia='0.00035939 0.014728 0.014707 -0.00020981 2.266e-05 -1.2e-07'/>
                <joint name='left-shin' type='hinge' range='-20 20' stiffness='1500' damping='0.1'/>
                <!-- Sophisticated shin -->
                <geom type='capsule' size='0.04' fromto='0 0 0 0.43476 0.02 0' rgba='1.0 0.0 0.0 1' class='collision'/>
                
                <body name='left-tarsus' pos='0.43476 0.02 0' xyaxes='0.52992 0.84805 0 -0.84805 0.52992 0'>
                  <inertial pos='0.11046 -0.03058 -0.00131' mass='0.782' fullinertia='0.00039238 0.013595 0.013674 0.00023651 -4.987e-05 -4.82e-06'/>
                  <joint name='left-tarsus' type='hinge' ref='58' range='50 170' damping='0.1'/>
                  <!-- Sophisticated tarsus -->
                  <geom type='capsule' size='0.04' fromto='-0.01269 -0.03059 0.00092 0.408 -0.04 0' rgba='1.0 0.0 0.0 1' class='collision'/>
                  
                  <body name='left-heel-spring' pos='-0.01269 -0.03059 0.00092' xyaxes='-0.91211 0.40829 0.036948 -0.40992 -0.90952 -0.068841'>
                    <inertial pos='0.081 0.0022 0' mass='0.126' fullinertia='2.959e-05 0.00022231 0.0002007 7.15e-06 -6e-07 1e-07'/>
                    <joint name='left-heel-spring' type='hinge' limited='false' stiffness='1250'/>
                    <!-- Sophisticated heel spring -->
                    <geom type='capsule' size='0.015' fromto='0 0 0 0.081 0.0022 0' rgba='1.0 0.0 0.0 1'/>
                  </body>
                  
                  <body name='left-foot-crank' pos='0.058 -0.034 0.02275'>
                    <inertial pos='0.00493 2e-05 -0.00215' mass='0.1261' fullinertia='2.6941e-05 4.9621e-05 6.3362e-05 -2.1e-09 -3.9623e-06 -1.09e-08'/>
                    <joint name='left-foot-crank' type='hinge' range='-140 -30' damping='1'/>
                    <!-- Sophisticated foot crank -->
                    <geom type='sphere' size='0.03' pos='0.00493 2e-05 -0.00215' rgba='1.0 0.0 0.0 1'/>
                    
                    <body name='left-plantar-rod' pos='0.055 0 -0.00791'>
                      <inertial pos='0.17792 0 0' mass='0.1186' fullinertia='2.779e-06 0.001774 0.001775 -2.34e-08 -8.1e-09 0'/>
                      <joint name='left-plantar-rod' type='hinge' limited='false'/>
                      <!-- Sophisticated plantar rod -->
                      <geom type='capsule' size='0.008' fromto='0 0 0 0.17792 0 0' rgba='1.0 0.0 0.0 1'/>
                    </body>
                  </body>
                  
                  <body name='left-foot' pos='0.408 -0.04 0'>
                    <inertial pos='0.00474 0.02748 -0.00014' mass='0.1498' fullinertia='0.00017388 0.00016793 0.00033261 0.00011814 1.36e-06 -4e-07'/>
                    <joint name='left-foot' type='hinge' range='-140 -30' damping='1' armature='0.01225'/>
                    <!-- Sophisticated foot -->
                    <geom type='capsule' size='0.02' fromto='-0.052821 0.092622 0 0.069746 -0.010224 0' rgba='1.0 0.0 0.0 1' friction='1.0 0.5 0.001' class='collision_left'/>
                  </body>
                </body>
              </body>
            </body>
          </body>
        </body>
      </body>
      
      <!-- COMPLETE CASSIE LEG STRUCTURE - RIGHT LEG -->
      <body name='right-hip-roll' pos='0.021 -0.135 -0.2' xyaxes='0 0 -1 0 1 0'>
        <inertial pos='-0.01793 0.0001 -0.04428' mass='1.82' fullinertia='0.003431 0.003793 0.002135 6.65e-07 -0.00084 -3.99e-06'/>
        <joint name='right-hip-roll' type='hinge' range='-22.5 15' damping='1' armature='0.038125'/>
        <!-- Sophisticated hip roll geometry (mirrored) -->
        <geom type='cylinder' size='0.06 0.1' pos='0 0 0' rgba='0.0 0.0 1.0 1'/>
        <!-- Visible gears/internal workings -->
        <geom type='cylinder' size='0.04 0.02' pos='0 0 0.08' rgba='0.1 0.3 0.1 0.8'/>
        <geom type='cylinder' size='0.04 0.02' pos='0 0 -0.08' rgba='0.1 0.3 0.1 0.8'/>
        
        <body name='right-hip-yaw' pos='0 0 -0.07' xyaxes='0 0 1 0 1 0'>
          <inertial pos='0 1e-05 -0.034277' mass='1.171' fullinertia='0.002443 0.002803 0.000842 4e-08 2.462e-07 2.71e-08'/>
          <joint name='right-hip-yaw' type='hinge' range='-22.5 22.5' damping='1' armature='0.038125'/>
          <!-- Sophisticated hip yaw geometry (mirrored) -->
          <geom type='capsule' size='0.05' fromto='-0.025 0 -0.015 0.025 0 -0.015' rgba='0.0 0.0 1.0 1'/>
          
          <body name='right-hip-pitch' pos='0 0 -0.09' xyaxes='0 0 -1 1 0 0'>
            <inertial pos='0.05946 5e-05 0.03581' mass='5.52' fullinertia='0.010898 0.029714 0.030257 -0.0002669 5.721e-05 -9.17e-06'/>
            <joint name='right-hip-pitch' type='hinge' range='-50 80' damping='1' armature='0.09344'/>
            <!-- Sophisticated hip pitch geometry (mirrored) -->
            <geom type='capsule' size='0.08' fromto='0 0 0.04 0.12 0 0.0355' rgba='0.0 0.0 1.0 1' class='collision'/>
            
            <body name='right-achilles-rod' pos='0 0 -0.045' xyaxes='0.7922 -0.60599 0.072096 0.60349 0.79547 0.054922'>
              <inertial pos='0.24719 0 0' mass='0.1567' fullinertia='3.754e-06 0.004487 0.004488 -3.74e-08 1.61e-08 0'/>
              <joint name='right-achilles-rod' type='ball' limited='false' damping='0.01'/>
              <!-- Sophisticated achilles rod (mirrored) -->
              <geom type='capsule' size='0.01' fromto='0 0 0 0.24719 0 0' rgba='0.2 0.2 0.2 1'/>
            </body>
            
            <body name='right-knee' pos='0.12 0 -0.0045' xyaxes='0.70711 -0.70711 0 0.70711 0.70711 0'>
              <inertial pos='0.023 0.03207 0.002181' mass='0.7578' fullinertia='0.001376 0.0010335 0.0021637 -0.00039744 4.085e-05 5.374e-05'/>
              <joint name='right-knee' type='hinge' ref='-45' range='-164 -37' damping='1' armature='0.09344'/>
              <!-- Sophisticated knee joint (mirrored) -->
              <geom type='sphere' size='0.08' pos='0.023 0.03207 0.002181' rgba='0.0 0.0 1.0 1'/>
              
              <body name='right-knee-spring' pos='0.06068 0.08241 0'>
                <inertial pos='0.0836 0.0034 0' mass='0.186' fullinertia='5.215e-05 0.00041205 0.0003669 6.87e-06 0 0'/>
                <!-- Sophisticated knee spring (mirrored) -->
                <geom type='capsule' size='0.02' fromto='0 0 0 0.0836 0.0034 0' rgba='0.2 0.2 0.2 1'/>
              </body>
              
              <body name='right-shin' pos='0.06068 0.04741 0'>
                <inertial pos='0.18338 0.001169 -0.0002123' mass='0.577' fullinertia='0.00035939 0.014728 0.014707 -0.00020981 -2.266e-05 1.2e-07'/>
                <joint name='right-shin' type='hinge' range='-20 20' stiffness='1500' damping='0.1'/>
                <!-- Sophisticated shin (mirrored) -->
                <geom type='capsule' size='0.04' fromto='0 0 0 0.43476 0.02 0' rgba='0.0 0.0 1.0 1' class='collision'/>
                
                <body name='right-tarsus' pos='0.43476 0.02 0' xyaxes='0.52992 0.84805 0 -0.84805 0.52992 0'>
                  <inertial pos='0.11046 -0.03058 0.00131' mass='0.782' fullinertia='0.00039238 0.013595 0.013674 0.00023651 4.987e-05 4.82e-06'/>
                  <joint name='right-tarsus' type='hinge' ref='58' range='50 170' damping='0.1'/>
                  <!-- Sophisticated tarsus (mirrored) -->
                  <geom type='capsule' size='0.04' fromto='-0.01269 -0.03059 -0.00092 0.408 -0.04 0' rgba='0.0 0.0 1.0 1' class='collision'/>
                  
                  <body name='right-heel-spring' pos='-0.01269 -0.03059 -0.00092' xyaxes='-0.91211 0.40829 -0.036948 -0.40992 -0.90952 0.068841'>
                    <inertial pos='0.081 0.0022 0' mass='0.126' fullinertia='2.959e-05 0.00022231 0.0002007 7.15e-06 6e-07 -1e-07'/>
                    <joint name='right-heel-spring' type='hinge' limited='false' stiffness='1250'/>
                    <!-- Sophisticated heel spring (mirrored) -->
                    <geom type='capsule' size='0.015' fromto='0 0 0 0.081 0.0022 0' rgba='0.2 0.2 0.2 1'/>
                  </body>
                  
                  <body name='right-foot-crank' pos='0.058 -0.034 -0.02275'>
                    <inertial pos='0.00493 2e-05 0.00215' mass='0.1261' fullinertia='2.6941e-05 4.9621e-05 6.3362e-05 -2.1e-09 3.9623e-06 1.09e-08'/>
                    <joint name='right-foot-crank' type='hinge' range='-140 -30' damping='1'/>
                    <!-- Sophisticated foot crank (mirrored) -->
                    <geom type='sphere' size='0.03' pos='0.00493 2e-05 0.00215' rgba='0.0 0.0 1.0 1'/>
                    
                    <body name='right-plantar-rod' pos='0.055 0 0.00791'>
                      <inertial pos='0.17792 0 0' mass='0.1186' fullinertia='2.779e-06 0.001774 0.001775 -2.34e-08 8.1e-09 0'/>
                      <joint name='right-plantar-rod' type='hinge' limited='false'/>
                      <!-- Sophisticated plantar rod (mirrored) -->
                      <geom type='capsule' size='0.008' fromto='0 0 0 0.17792 0 0' rgba='0.2 0.2 0.2 1'/>
                    </body>
                  </body>
                  
                  <body name='right-foot' pos='0.408 -0.04 0'>
                    <inertial pos='0.00474 0.02748 0.00014' mass='0.1498' fullinertia='0.00017388 0.00016793 0.00033261 0.00011814 -1.36e-06 4e-07'/>
                    <joint name='right-foot' type='hinge' range='-140 -30' damping='1' armature='0.01225'/>
                    <!-- Sophisticated foot (mirrored) -->
                    <geom type='capsule' size='0.02' fromto='-0.052821 0.092622 0 0.069746 -0.010224 0' rgba='0.0 0.0 1.0 1' friction='1.0 0.5 0.001' class='collision_right'/>
                  </body>
                </body>
              </body>
            </body>
          </body>
        </body>
      </body>
    </body>
  </worldbody>
  
  <actuator>
    <!-- Sophisticated thruster pitch actuators -->
    <motor joint='thruster_left_pitch' name='thruster-left-pitch-motor' gear='50'/>
    <motor joint='thruster_right_pitch' name='thruster-right-pitch-motor' gear='50'/>
    
    <!-- Complete Cassie leg actuators -->
    <motor joint='left-hip-roll' name='left-hip-roll-motor' gear='50'/>
    <motor joint='left-hip-yaw' name='left-hip-yaw-motor' gear='50'/>
    <motor joint='left-hip-pitch' name='left-hip-pitch-motor' gear='50'/>
    <motor joint='left-knee' name='left-knee-motor' gear='50'/>
    <motor joint='left-foot-crank' name='left-foot-crank-motor' gear='50'/>
    <motor joint='left-foot' name='left-foot-motor' gear='50'/>
    <motor joint='right-hip-roll' name='right-hip-roll-motor' gear='50'/>
    <motor joint='right-hip-yaw' name='right-hip-yaw-motor' gear='50'/>
    <motor joint='right-hip-pitch' name='right-hip-pitch-motor' gear='50'/>
    <motor joint='right-knee' name='right-knee-motor' gear='50'/>
    <motor joint='right-foot-crank' name='right-foot-crank-motor' gear='50'/>
    <motor joint='right-foot' name='right-foot-motor' gear='50'/>
  </actuator>
  
  <sensor>
    <!-- Sophisticated thruster pitch sensors -->
    <jointpos joint='thruster_left_pitch' name='thruster-left-pitch-pos'/>
    <jointpos joint='thruster_right_pitch' name='thruster-right-pitch-pos'/>
    <jointvel joint='thruster_left_pitch' name='thruster-left-pitch-vel'/>
    <jointvel joint='thruster_right_pitch' name='thruster-right-pitch-vel'/>
    
    <!-- Complete Cassie leg position sensors -->
    <jointpos joint='left-hip-roll' name='left-hip-roll-pos'/>
    <jointpos joint='left-hip-yaw' name='left-hip-yaw-pos'/>
    <jointpos joint='left-hip-pitch' name='left-hip-pitch-pos'/>
    <jointpos joint='left-knee' name='left-knee-pos'/>
    <jointpos joint='left-foot-crank' name='left-foot-crank-pos'/>
    <jointpos joint='left-foot' name='left-foot-pos'/>
    <jointpos joint='right-hip-roll' name='right-hip-roll-pos'/>
    <jointpos joint='right-hip-yaw' name='right-hip-yaw-pos'/>
    <jointpos joint='right-hip-pitch' name='right-hip-pitch-pos'/>
    <jointpos joint='right-knee' name='right-knee-pos'/>
    <jointpos joint='right-foot-crank' name='right-foot-crank-pos'/>
    <jointpos joint='right-foot' name='right-foot-pos'/>
    
    <!-- Complete Cassie leg velocity sensors -->
    <jointvel joint='left-hip-roll' name='left-hip-roll-vel'/>
    <jointvel joint='left-hip-yaw' name='left-hip-yaw-vel'/>
    <jointvel joint='left-hip-pitch' name='left-hip-pitch-vel'/>
    <jointvel joint='left-knee' name='left-knee-vel'/>
    <jointvel joint='left-foot-crank' name='left-foot-crank-vel'/>
    <jointvel joint='left-foot' name='left-foot-vel'/>
    <jointvel joint='right-hip-roll' name='right-hip-roll-vel'/>
    <jointvel joint='right-hip-yaw' name='right-hip-yaw-vel'/>
    <jointvel joint='right-hip-pitch' name='right-hip-pitch-vel'/>
    <jointvel joint='right-knee' name='right-knee-vel'/>
    <jointvel joint='right-foot-crank' name='right-foot-crank-vel'/>
    <jointvel joint='right-foot' name='right-foot-vel'/>
    
    <!-- IMU sensors -->
    <accelerometer site='imu' name='main-body-accel'/>
    <gyro site='imu' name='main-body-gyro'/>
  </sensor>
</mujoco>
